Workbook
Name tgr: '05_Germany DCF'!$D$8
Name wacc: '05_Germany DCF'!$D$7

Sheet 01_Cover
B2: Deutsche Telekom AG
B3: Equity Research & Valuation Project
B4: Simon Norrman - Summer 2026
B6: Methods used:
B7: DCF
B8: Trading Comps
B9: Precedent Transactions
B10: SOTP

Sheet 03_Historical Financials
B2: Historical Financials
B4: €m
A5: x | B5: Historicals | C5: 2021 | D5: 2022 | E5: 2023 | F5: 2024 | G5: 2025
B6: Revenue | C6: 107610 | D6: 114197 | E6: 111970 | F6: 115769 | G6: 119081
B7: EBITDA | C7: 37330 | D7: 40208 | E7: 40497 | F7: 43021 | G7: 44244
B8: EBITDA Margin % | C8: =C7/C6 -> 0.34690085 | D8: =D7/D6 -> 0.35209331 | E8: =E7/E6 -> 0.36167723 | F8: =F7/F6 -> 0.37161071 | G8: =G7/G6 -> 0.37154542
B9: D&A | C9: 27091 | D9: 27635 | E9: 23975 | F9: 24027 | G9: 24009
B10: EBIT | C10: 12580 | D10: 15414 | E10: 20798 | F10: 26277 | G10: 24822
B11: EBIT Margin % | C11: =C10/C6 -> 0.11690363 | D11: =D10/D6 -> 0.13497728 | E11: =E10/E6 -> 0.18574618 | F11: =F10/F6 -> 0.22697786 | G11: =G10/G6 -> 0.20844635
B12: Net Income | C12: 4176 | D12: 8001 | E12: 17788 | F12: 11209 | G12: 9609
B13: Net Margin % | C13: =C12/C6 -> 0.038806802 | D13: =D12/D6 -> 0.070063137 | E13: =E12/E6 -> 0.15886398 | F13: =F12/F6 -> 0.09682212 | G13: =G12/G6 -> 0.080692974
B14: CapEx | C14: -26366 | D14: -24114 | E14: -17866 | F14: -19171 | G14: -19256
B15: CapEx % Revenue | C15: =C14/C6 -> -0.2450144 | D15: =D14/D6 -> -0.21116141 | E15: =E14/E6 -> -0.1595606 | F15: =F14/F6 -> -0.16559701 | G15: =G14/G6 -> -0.16170506
B16: FCF | C16: 8810 | D16: 11470 | E16: 16141 | F16: 19156 | G16: 19546
B17: FCF Margin % | C17: =C16/C6 -> 0.081869715 | D17: =D16/D6 -> 0.10044047 | E17: =E16/E6 -> 0.14415468 | F17: =F16/F6 -> 0.16546744 | G17: =G16/G6 -> 0.16414038
B18: Net Debt | C18: 100649 | D18: 103733 | E18: 93746 | F18: 99316 | G18: 98067

Sheet 04_Segment Financials
B2: Segment Financials
B4: €m
A5: x | B5: Segment Financials | C5: 2021 | D5: 2022 | E5: 2023 | F5: 2024 | G5: 2025 | I5: For Comps
B6: Germany | I6: Revenue excl. TMUS | J6: =G7+G18+G29 -> 42365
B7: Revenue | C7: 24050 | D7: 24505 | E7: 25187 | F7: 25711 | G7: 25610 | I7: EBITDA excl. TMUS | J7: =G9+G20+G31 -> 15798
B8: Revenue Growth % | C8: - | D8: =D7/C7-1 -> 0.018918919 | E8: =E7/D7-1 -> 0.027831055 | F8: =F7/E7-1 -> 0.020804383 | G8: =G7/F7-1 -> -0.0039282797 | I8: EBIT excl. TMUS | J8: =G11+G22+G33 -> 8519
B9: EBITDA | C9: 9536 | D9: 9837 | E9: 10238 | F9: 10516 | G9: 10694
B10: EBITDA Margin % | C10: =C9/C7 -> 0.39650728 | D10: =D9/D7 -> 0.40142828 | E10: =E9/E7 -> 0.40647953 | F10: =F9/F7 -> 0.40900782 | G10: =G9/G7 -> 0.41757126
B11: EBIT | C11: =C9-C13 -> 5530 | D11: =D9-D13 -> 5832 | E11: =E9-E13 -> 6027 | F11: =F9-F13 -> 6137 | G11: =G9-G13 -> 6214
B12: EBIT Margin % | C12: =C11/C7 -> 0.22993763 | D12: =D11/D7 -> 0.23799225 | E12: =E11/E7 -> 0.23929011 | F12: =F11/F7 -> 0.23869161 | G12: =G11/G7 -> 0.24263959
B13: D&A | C13: 4006 | D13: 4005 | E13: 4211 | F13: 4379 | G13: 4480
B14: D&A % Revenue | C14: =C13/C7 -> 0.16656965 | D14: =D13/D7 -> 0.16343603 | E14: =E13/E7 -> 0.16718942 | F14: =F13/F7 -> 0.17031621 | G14: =G13/G7 -> 0.17493167
B15: Cash CapEx | C15: 4119 | D15: 4399 | E15: 4587 | F15: 4782 | G15: 4870
B16: CapEx % Revenue | C16: =C15/C7 -> 0.17126819 | D16: =D15/D7 -> 0.17951438 | E16: =E15/E7 -> 0.18211776 | F16: =F15/F7 -> 0.18599043 | G16: =G15/G7 -> 0.19016009
B17: Europe
B18: Revenue | C18: 11294 | D18: 11158 | E18: 11790 | F18: 12347 | G18: 12652
B19: Revenue Growth % | C19: - | D19: =D18/C18-1 -> -0.012041792 | E19: =E18/D18-1 -> 0.056640975 | F19: =F18/E18-1 -> 0.047243427 | G19: =G18/F18-1 -> 0.024702357
B20: EBITDA | C20: 4007 | D20: 3964 | E20: 4114 | F20: 4431 | G20: 4677
B21: EBITDA Margin % | C21: =C20/C18 -> 0.35479015 | D21: =D20/D18 -> 0.3552608 | E21: =E20/E18 -> 0.34893978 | F21: =F20/F18 -> 0.3588726 | G21: =G20/G18 -> 0.36966488
B22: EBIT | C22: =C20-C24 -> 1446 | D22: =D20-D24 -> 1520 | E22: =E20-E24 -> 1614 | F22: =F20-F24 -> 1907 | G22: =G20-G24 -> 2130
B23: EBIT Margin % | C23: =C22/C18 -> 0.12803258 | D23: =D22/D18 -> 0.13622513 | E23: =E22/E18 -> 0.13689567 | F23: =F22/F18 -> 0.15445047 | G23: =G22/G18 -> 0.16835283
B24: D&A | C24: 2561 | D24: 2444 | E24: 2500 | F24: 2524 | G24: 2547
B25: D&A % Revenue | C25: =C24/C18 -> 0.22675757 | D25: =D24/D18 -> 0.21903567 | E25: =E24/E18 -> 0.21204411 | F25: =F24/F18 -> 0.20442213 | G25: =G24/G18 -> 0.20131205
B26: Cash CapEx | C26: 1905 | D26: 1872 | E26: 2049 | F26: 1919 | G26: 2250
B27: CapEx % Revenue | C27: =C26/C18 -> 0.16867363 | D27: =D26/D18 -> 0.167772 | E27: =E26/E18 -> 0.17379135 | F27: =F26/F18 -> 0.15542237 | G27: =G26/G18 -> 0.1778375
B28: T-Systems
B29: Revenue | C29: 3759 | D29: 3811 | E29: 3896 | F29: 4004 | G29: 4103
B30: Revenue Growth % | C30: - | D30: =D29/C29-1 -> 0.013833466 | E30: =E29/D29-1 -> 0.022303857 | F30: =F29/E29-1 -> 0.027720739 | G30: =G29/F29-1 -> 0.024725275
B31: EBITDA | C31: 271 | D31: 284 | E31: 321 | F31: 369 | G31: 427
B32: EBITDA Margin % | C32: =C31/C29 -> 0.072093642 | D32: =D31/D29 -> 0.074521123 | E32: =E31/E29 -> 0.082392197 | F32: =F31/F29 -> 0.092157842 | G32: =G31/G29 -> 0.10407019
B33: EBIT | C33: =C31-C35 -> 28 | D33: =D31-D35 -> 56 | E33: =E31-E35 -> 103 | F33: =F31-F35 -> 148 | G33: =G31-G35 -> 175
B34: EBIT Margin % | C34: =C33/C29 -> 0.0074487896 | D34: =D33/D29 -> 0.014694306 | E34: =E33/E29 -> 0.026437372 | F34: =F33/F29 -> 0.036963037 | G34: =G33/G29 -> 0.042651718
B35: D&A | C35: 243 | D35: 228 | E35: 218 | F35: 221 | G35: 252
B36: D&A % Revenue | C36: =C35/C29 -> 0.064644852 | D36: =D35/D29 -> 0.059826817 | E36: =E35/E29 -> 0.055954825 | F36: =F35/F29 -> 0.055194805 | G36: =G35/G29 -> 0.061418474
B37: Cash CapEx | C37: 235 | D37: 221 | E37: 210 | F37: 229 | G37: 220
B38: CapEx % Revenue | C38: =C37/C29 -> 0.062516627 | D38: =D37/D29 -> 0.057990029 | E38: =E37/E29 -> 0.053901437 | F38: =F37/F29 -> 0.057192807 | G38: =G37/G29 -> 0.053619303
B39: TMUS
B40: Revenue | C40: 67791 | D40: 75436 | E40: 72436 | F40: 75046 | G40: 78097
B41: Revenue Growth % | C41: - | D41: =D40/C40-1 -> 0.11277308 | E41: =E40/D40-1 -> -0.039768811 | F41: =F40/E40-1 -> 0.036031807 | G41: =G40/F40-1 -> 0.040655065
B42: EBITDA | C42: 22697 | D42: 25614 | E42: 26409 | F42: 28545 | G42: 29252
...

Sheet WACC Germany
B2: WACC
A4: x | B4: WACC
B5: WACC = (% Equity x Cost of Equity) + (% Debt x Cost of Debt x (1 -Tax rate))
B6: Cost of Equity = Risk Free Rate + (Beta x (Expected Market Return - Risk Free Rate))
B8: Debt | D8: 143603000000
B9: % Debt | D9: =D8/D20 -> 0.51414772
B10: Cost of Debt | D10: 0.051
B11: Tax Rate | D11: 0.31
B13: Equity Value | D13: 1.357e+11
B14: % Equity | D14: =D13/D20 -> 0.48585228
B15: Cost of Equity | D15: =D16+D17*D18 -> 0.07575
B16: Risk Free Rate | D16: 0.029
B17: Beta | D17: 0.85
B18: Market Risk Premium | D18: 0.055
B20: Debt + Equity | D20: =D8+D13 -> 279303000000
A22: x | B22: WACC | D22: =(D9*D10*(1-D11))+(D14*D15) -> 0.054896169

Sheet 05_Germany DCF
B2: Germany Telekom DCF
A5: x | B5: Assumptions
B6: Valuation Assumptions
B7: WACC | D7: ='WACC Germany'!D22 -> 0.054896169
B8: TGR | D8: 0.015
B9: Tax Rate | D9: 0.31
B11: Operating Assumptions
B12: Germany | E12: 2026E | F12: 2027E | G12: 2028E | H12: 2029E | I12: 2030E
B13: Revenue Growth % | E13: 0.015 | F13: 0.018 | G13: 0.02 | H13: 0.02 | I13: 0.02
B14: EBIT Margin % | E14: 0.23 | F14: 0.232 | G14: 0.234 | H14: 0.235 | I14: 0.235
B15: D&A % of Revenue | E15: 0.175 | F15: 0.173 | G15: 0.17 | H15: 0.168 | I15: 0.175
B16: CapEx % of Revenue | E16: 0.19 | F16: 0.188 | G16: 0.185 | H16: 0.18 | I16: 0.175
B17: Change in NWC % of Revenue | E17: 0.012 | F17: 0.012 | G17: 0.012 | H17: 0.012 | I17: 0.012
J20: 1 | K20: =J20+1 -> 2 | L20: =K20+1 -> 3 | M20: =L20+1 -> 4 | N20: =M20+1 -> 5
A21: x | B21: Income Statement | E21: 2021 | F21: =E21+1 -> 2022 | G21: =F21+1 -> 2023 | H21: =G21+1 -> 2024 | I21: =H21+1 -> 2025 | J21: =I21+1 -> 2026 | K21: =J21+1 -> 2027 | L21: =K21+1 -> 2028 | M21: =L21+1 -> 2029 | N21: =M21+1 -> 2030
B22: Revenue | E22: ='04_Segment Financials'!C7 -> 24050 | F22: ='04_Segment Financials'!D7 -> 24505 | G22: ='04_Segment Financials'!E7 -> 25187 | H22: ='04_Segment Financials'!F7 -> 25711 | I22: ='04_Segment Financials'!G7 -> 25610 | J22: =I22*(1+E13) -> 25994.15 | K22: =J22*(1+F13) -> 26462.045 | L22: =K22*(1+G13) -> 26991.286 | M22: =L22*(1+H13) -> 27531.111 | N22: =M22*(1+I13) -> 28081.734
B23: % growth | E23: - | F23: =F22/E22-1 -> 0.018918919 | G23: =G22/F22-1 -> 0.027831055 | H23: =H22/G22-1 -> 0.020804383 | I23: =I22/H22-1 -> -0.0039282797 | J23: =J22/I22-1 -> 0.015 | K23: =K22/J22-1 -> 0.018 | L23: =L22/K22-1 -> 0.02 | M23: =M22/L22-1 -> 0.02 | N23: =N22/M22-1 -> 0.02
B25: EBIT | E25: ='04_Segment Financials'!C11 -> 5530 | F25: ='04_Segment Financials'!D11 -> 5832 | G25: ='04_Segment Financials'!E11 -> 6027 | H25: ='04_Segment Financials'!F11 -> 6137 | I25: ='04_Segment Financials'!G11 -> 6214 | J25: =J22*E14 -> 5978.6545 | K25: =K22*F14 -> 6139.1944 | L25: =L22*G14 -> 6315.9608 | M25: =M22*H14 -> 6469.8112 | N25: =N22*I14 -> 6599.2074
B26: % of sales | E26: =E25/E$22 -> 0.22993763 | F26: =F25/F$22 -> 0.23799225 | G26: =G25/G$22 -> 0.23929011 | H26: =H25/H$22 -> 0.23869161 | I26: =I25/I$22 -> 0.24263959 | J26: =J25/J$22 -> 0.23 | K26: =K25/K$22 -> 0.232 | L26: =L25/L$22 -> 0.234 | ... N26: =N25/N$22 -> 0.235
B28: Taxes | E28: =E25*$D$9 -> 1714.3 | F28: =F25*$D$9 -> 1807.92 | G28: =G25*$D$9 -> 1868.37 | H28: =H25*$D$9 -> 1902.47 | I28: =I25*$D$9 -> 1926.34 | J28: =J25*$D$9 -> 1853.3829 | K28: =K25*$D$9 -> 1903.1503 | L28: =L25*$D$9 -> 1957.9479 | ... N28: =N25*$D$9 -> 2045.7543
B29: % of EBIT | E29: =E28/E$25 -> 0.31 | F29: =F28/F$25 -> 0.31 | G29: =G28/G$25 -> 0.31 | H29: =H28/H$25 -> 0.31 | I29: =I28/I$25 -> 0.31 | J29: =J28/J$25 -> 0.31 | K29: =K28/K$25 -> 0.31 | L29: =L28/L$25 -> 0.31 | ... N29: =N28/N$25 -> 0.31
A31: x | B31: Cash Flow Items | E31: 2021 | F31: =E31+1 -> 2022 | G31: =F31+1 -> 2023 | H31: =G31+1 -> 2024 | I31: =H31+1 -> 2025 | J31: =I31+1 -> 2026 | K31: =J31+1 -> 2027 | L31: =K31+1 -> 2028 | M31: =L31+1 -> 2029 | N31: =M31+1 -> 2030
B32: D&A | E32: ='04_Segment Financials'!C13 -> 4006 | F32: ='04_Segment Financials'!D13 -> 4005 | G32: ='04_Segment Financials'!E13 -> 4211 | H32: ='04_Segment Financials'!F13 -> 4379 | I32: ='04_Segment Financials'!G13 -> 4480 | J32: =J22*E15 -> 4548.9762 | K32: =K22*F15 -> 4577.9337 | L32: =L22*G15 -> 4588.5186 | M32: =M22*H15 -> 4625.2267 | N32: =N22*I15 -> 4914.3034
B33: % of sales | E33: =E32/E$22 -> 0.16656965 | F33: =F32/F$22 -> 0.16343603 | G33: =G32/G$22 -> 0.16718942 | H33: =H32/H$22 -> 0.17031621 | I33: =I32/I$22 -> 0.17493167 | J33: =J32/J$22 -> 0.175 | K33: =K32/K$22 -> 0.173 | L33: =L32/L$22 -> 0.17 | ... N33: =N32/N$22 -> 0.175
B35: CapEx | E35: ='04_Segment Financials'!C15 -> 4119 | F35: ='04_Segment Financials'!D15 -> 4399 | G35: ='04_Segment Financials'!E15 -> 4587 | H35: ='04_Segment Financials'!F15 -> 4782 | I35: ='04_Segment Financials'!G15 -> 4870 | J35: =J22*E16 -> 4938.8885 | K35: =K22*F16 -> 4974.8644 | L35: =L22*G16 -> 4993.3878 | M35: =M22*H16 -> 4955.6 | N35: =N22*I16 -> 4914.3034
B36: % of sales | E36: =E35/E$22 -> 0.17126819 | F36: =F35/F$22 -> 0.17951438 | G36: =G35/G$22 -> 0.18211776 | H36: =H35/H$22 -> 0.18599043 | I36: =I35/I$22 -> 0.19016009 | J36: =J35/J$22 -> 0.19 | K36: =K35/K$22 -> 0.188 | L36: =L35/L$22 -> 0.185 | ... N36: =N35/N$22 -> 0.175
B38: Change in NWC | E38: - | F38: ='04_Segment Financials'!D55 -> -0.94696854 | G38: ='04_Segment Financials'!E55 -> 282.89999 | H38: ='04_Segment Financials'!F55 -> 417.40319 | I38: ='04_Segment Financials'!G55 -> 220.88447 | J38: =J22*E17 -> 311.9298 | K38: =K22*F17 -> 317.54454 | L38: =L22*G17 -> 323.89543 | M38: =M22*H17 -> 330.37334 | N38: =N22*I17 -> 336.9808
B39: % of sales | F39: =F38/F$22 -> -3.8643891e-05 | G39: =G38/G$22 -> 0.011231984 | H39: =H38/H$22 -> 0.016234421 | I39: =I38/I$22 -> 0.0086249307 | J39: =J38/J$22 -> 0.012 | K39: =K38/K$22 -> 0.012 | L39: =L38/L$22 -> 0.012 | M39: =M38/M$22 -> 0.012 | N39: =N38/N$22 -> 0.012
J40: 1 | K40: =J40+1 -> 2 | L40: =K40+1 -> 3 | M40: =L40+1 -> 4 | N40: =M40+1 -> 5
A41: x | B41: DCF | E41: 2021 | F41: =E41+1 -> 2022 | G41: =F41+1 -> 2023 | H41: =G41+1 -> 2024 | I41: =H41+1 -> 2025 | J41: =I41+1 -> 2026 | K41: =J41+1 -> 2027 | L41: =K41+1 -> 2028 | M41: =L41+1 -> 2029 | N41: =M41+1 -> 2030
B42: Revenue | E42: =E22 -> 24050 | F42: =F22 -> 24505 | G42: =G22 -> 25187 | H42: =H22 -> 25711 | I42: =I22 -> 25610 | J42: =I42*(1+J43) -> 25994.15 | K42: =J42*(1+K43) -> 26462.045 | L42: =K42*(1+L43) -> 26991.286 | M42: =L42*(1+M43) -> 27531.111 | N42: =M42*(1+N43) -> 28081.734
B43: % growth | F43: =F42/E42-1 -> 0.018918919 | G43: =G42/F42-1 -> 0.027831055 | H43: =H42/G42-1 -> 0.020804383 | I43: =I42/H42-1 -> -0.0039282797 | J43: =J23 -> 0.015 | K43: =K23 -> 0.018 | L43: =L23 -> 0.02 | M43: =M23 -> 0.02 | N43: =N23 -> 0.02
B45: EBIT | E45: =E25 -> 5530 | F45: =F25 -> 5832 | G45: =G25 -> 6027 | H45: =H25 -> 6137 | I45: =I25 -> 6214 | J45: =J46*J42 -> 5978.6545 | K45: =K46*K42 -> 6139.1944 | L45: =L46*L42 -> 6315.9608 | M45: =M46*M42 -> 6469.8112 | N45: =N46*N42 -> 6599.2074
B46: % margin | E46: =E45/E42 -> 0.22993763 | F46: =F45/F42 -> 0.23799225 | G46: =G45/G42 -> 0.23929011 | H46: =H45/H42 -> 0.23869161 | I46: =I45/I42 -> 0.24263959 | J46: =J26 -> 0.23 | K46: =K26 -> 0.232 | L46: =L26 -> 0.234 | M46: =M26 -> 0.235 | N46: =N26 -> 0.235
B48: Taxes | E48: =E28 -> 1714.3 | F48: =F28 -> 1807.92 | G48: =G28 -> 1868.37 | H48: =H28 -> 1902.47 | I48: =I28 -> 1926.34 | J48: =J49*J45 -> 1853.3829 | K48: =K49*K45 -> 1903.1503 | L48: =L49*L45 -> 1957.9479 | M48: =M49*M45 -> 2005.6415 | N48: =N49*N45 -> 2045.7543
B49: % of EBIT | E49: =E48/E45 -> 0.31 | F49: =F48/F45 -> 0.31 | G49: =G48/G45 -> 0.31 | H49: =H48/H45 -> 0.31 | I49: =I48/I45 -> 0.31 | J49: =J29 -> 0.31 | K49: =K29 -> 0.31 | L49: =L29 -> 0.31 | M49: =M29 -> 0.31 | N49: =N29 -> 0.31
B51: NOPAT | J51: =J45-J48 -> 4125.2716 | K51: =K45-K48 -> 4236.0441 | L51: =L45-L48 -> 4358.013 | M51: =M45-M48 -> 4464.1697 | N51: =N45-N48 -> 4553.4531
B53: D&A | E53: =E32 -> 4006 | F53: =F32 -> 4005 | G53: =G32 -> 4211 | H53: =H32 -> 4379 | I53: =I32 -> 4480 | J53: =J32 -> 4548.9762 | K53: =K32 -> 4577.9337 | L53: =L32 -> 4588.5186 | ... N53: =N32 -> 4914.3034
B54: % of sales | E54: =E53/E$42 -> 0.16656965 | F54: =F53/F$42 -> 0.16343603 | G54: =G53/G$42 -> 0.16718942 | H54: =H53/H$42 -> 0.17031621 | I54: =I53/I$42 -> 0.17493167 | J54: =J53/J$42 -> 0.175 | K54: =K53/K$42 -> 0.173 | L54: =L53/L$42 -> 0.17 | ... N54: =N53/N$42 -> 0.175
B56: CapEx | E56: =E35 -> 4119 | F56: =F35 -> 4399 | G56: =G35 -> 4587 | H56: =H35 -> 4782 | I56: =I35 -> 4870 | J56: =J35 -> 4938.8885 | K56: =K35 -> 4974.8644 | L56: =L35 -> 4993.3878 | ... N56: =N35 -> 4914.3034
...

Sheet WACC Europe
B2: WACC
A4: x | B4: WACC
B5: WACC = (% Equity x Cost of Equity) + (% Debt x Cost of Debt x (1 -Tax rate))
B6: Cost of Equity = Risk Free Rate + (Beta x (Expected Market Return - Risk Free Rate))
B8: Debt | D8: 143603000000
B9: % Debt | D9: =D8/D20 -> 0.51414772
B10: Cost of Debt | D10: 0.051
B11: Tax Rate | D11: 0.25
B13: Equity Value | D13: 1.357e+11
B14: % Equity | D14: =D13/D20 -> 0.48585228
B15: Cost of Equity | D15: =D16+D17*D18 -> 0.07575
B16: Risk Free Rate | D16: 0.029
B17: Beta | D17: 0.85
B18: Market Risk Premium | D18: 0.055
B20: Debt + Equity | D20: =D8+D13 -> 279303000000
A22: x | B22: WACC | D22: =(D9*D10*(1-D11))+(D14*D15) -> 0.056469461

Sheet 06_Europe DCF
B2: Europe Telekom DCF
A5: x | B5: Assumptions
B6: Valuation Assumptions
B7: WACC | D7: ='WACC Europe'!D22 -> 0.056469461
B8: TGR | D8: 0.015
B9: Tax Rate | D9: 0.25
B11: Operating Assumptions
B12: Europe | E12: 2026E | F12: 2027E | G12: 2028E | H12: 2029E | I12: 2030E
B13: Revenue Growth % | E13: 0.025 | F13: 0.025 | G13: 0.02 | H13: 0.02 | I13: 0.02
B14: EBIT Margin % | E14: 0.2 | F14: 0.203 | G14: 0.206 | H14: 0.208 | I14: 0.21
B15: D&A % of Revenue | E15: 0.195 | F15: 0.19 | G15: 0.185 | H15: 0.18 | I15: 0.178
B16: CapEx % of Revenue | E16: 0.18 | F16: 0.18 | G16: 0.178 | H16: 0.178 | I16: 0.178
B17: Change in NWC % of Revenue | E17: 0.012 | F17: 0.012 | G17: 0.012 | H17: 0.012 | I17: 0.012
J20: 1 | K20: =J20+1 -> 2 | L20: =K20+1 -> 3 | M20: =L20+1 -> 4 | N20: =M20+1 -> 5
A21: x | B21: Income Statement | E21: 2021 | F21: =E21+1 -> 2022 | G21: =F21+1 -> 2023 | H21: =G21+1 -> 2024 | I21: =H21+1 -> 2025 | J21: =I21+1 -> 2026 | K21: =J21+1 -> 2027 | L21: =K21+1 -> 2028 | M21: =L21+1 -> 2029 | N21: =M21+1 -> 2030
B22: Revenue | E22: ='04_Segment Financials'!C18 -> 11294 | F22: ='04_Segment Financials'!D18 -> 11158 | G22: ='04_Segment Financials'!E18 -> 11790 | H22: ='04_Segment Financials'!F18 -> 12347 | I22: ='04_Segment Financials'!G18 -> 12652 | J22: =I22*(1+E13) -> 12968.3 | K22: =J22*(1+F13) -> 13292.507 | L22: =K22*(1+G13) -> 13558.358 | M22: =L22*(1+H13) -> 13829.525 | N22: =M22*(1+I13) -> 14106.115
B23: % growth | E23: - | F23: =F22/E22-1 -> -0.012041792 | G23: =G22/F22-1 -> 0.056640975 | H23: =H22/G22-1 -> 0.047243427 | I23: =I22/H22-1 -> 0.024702357 | J23: =J22/I22-1 -> 0.025 | K23: =K22/J22-1 -> 0.025 | L23: =L22/K22-1 -> 0.02 | M23: =M22/L22-1 -> 0.02 | N23: =N22/M22-1 -> 0.02
B25: EBIT | E25: ='04_Segment Financials'!C22 -> 1446 | F25: ='04_Segment Financials'!D22 -> 1520 | G25: ='04_Segment Financials'!E22 -> 1614 | H25: ='04_Segment Financials'!F22 -> 1907 | I25: ='04_Segment Financials'!G22 -> 2130 | J25: =J22*E14 -> 2593.66 | K25: =K22*F14 -> 2698.379 | L25: =L22*G14 -> 2793.0217 | M25: =M22*H14 -> 2876.5412 | N25: =N22*I14 -> 2962.2842
B26: % of sales | E26: =E25/E$22 -> 0.12803258 | F26: =F25/F$22 -> 0.13622513 | G26: =G25/G$22 -> 0.13689567 | H26: =H25/H$22 -> 0.15445047 | I26: =I25/I$22 -> 0.16835283 | J26: =J25/J$22 -> 0.2 | K26: =K25/K$22 -> 0.203 | L26: =L25/L$22 -> 0.206 | ... N26: =N25/N$22 -> 0.21
B28: Taxes | E28: =E25*$D$9 -> 361.5 | F28: =F25*$D$9 -> 380 | G28: =G25*$D$9 -> 403.5 | H28: =H25*$D$9 -> 476.75 | I28: =I25*$D$9 -> 532.5 | J28: =J25*$D$9 -> 648.415 | K28: =K25*$D$9 -> 674.59476 | L28: =L25*$D$9 -> 698.25542 | ... N28: =N25*$D$9 -> 740.57105
B29: % of EBIT | E29: =E28/E$25 -> 0.25 | F29: =F28/F$25 -> 0.25 | G29: =G28/G$25 -> 0.25 | H29: =H28/H$25 -> 0.25 | I29: =I28/I$25 -> 0.25 | J29: =J28/J$25 -> 0.25 | K29: =K28/K$25 -> 0.25 | L29: =L28/L$25 -> 0.25 | ... N29: =N28/N$25 -> 0.25
A31: x | B31: Cash Flow Items | E31: 2021 | F31: =E31+1 -> 2022 | G31: =F31+1 -> 2023 | H31: =G31+1 -> 2024 | I31: =H31+1 -> 2025 | J31: =I31+1 -> 2026 | K31: =J31+1 -> 2027 | L31: =K31+1 -> 2028 | M31: =L31+1 -> 2029 | N31: =M31+1 -> 2030
B32: D&A | E32: ='04_Segment Financials'!C24 -> 2561 | F32: ='04_Segment Financials'!D24 -> 2444 | G32: ='04_Segment Financials'!E24 -> 2500 | H32: ='04_Segment Financials'!F24 -> 2524 | I32: ='04_Segment Financials'!G24 -> 2547 | J32: =J22*E15 -> 2528.8185 | K32: =K22*F15 -> 2525.5764 | L32: =L22*G15 -> 2508.2962 | M32: =M22*H15 -> 2489.3145 | N32: =N22*I15 -> 2510.8885
B33: % of sales | E33: =E32/E$22 -> 0.22675757 | F33: =F32/F$22 -> 0.21903567 | G33: =G32/G$22 -> 0.21204411 | H33: =H32/H$22 -> 0.20442213 | I33: =I32/I$22 -> 0.20131205 | J33: =J32/J$22 -> 0.195 | K33: =K32/K$22 -> 0.19 | L33: =L32/L$22 -> 0.185 | ... N33: =N32/N$22 -> 0.178
B35: CapEx | E35: ='04_Segment Financials'!C26 -> 1905 | F35: ='04_Segment Financials'!D26 -> 1872 | G35: ='04_Segment Financials'!E26 -> 2049 | H35: ='04_Segment Financials'!F26 -> 1919 | I35: ='04_Segment Financials'!G26 -> 2250 | J35: =J22*E16 -> 2334.294 | K35: =K22*F16 -> 2392.6513 | L35: =L22*G16 -> 2413.3877 | M35: =M22*H16 -> 2461.6554 | N35: =N22*I16 -> 2510.8885
B36: % of sales | E36: =E35/E$22 -> 0.16867363 | F36: =F35/F$22 -> 0.167772 | G36: =G35/G$22 -> 0.17379135 | H36: =H35/H$22 -> 0.15542237 | I36: =I35/I$22 -> 0.1778375 | J36: =J35/J$22 -> 0.18 | K36: =K35/K$22 -> 0.18 | L36: =L35/L$22 -> 0.178 | ... N36: =N35/N$22 -> 0.178
B38: Change in NWC | E38: - | F38: ='04_Segment Financials'!D57 -> -10.52784 | G38: ='04_Segment Financials'!E57 -> 141.44379 | H38: ='04_Segment Financials'!F57 -> 212.4433 | I38: ='04_Segment Financials'!G57 -> 128.54293 | J38: =J22*E17 -> 155.6196 | K38: =K22*F17 -> 159.51009 | L38: =L22*G17 -> 162.70029 | M38: =M22*H17 -> 165.9543 | N38: =N22*I17 -> 169.27338
B39: % of sales | F39: =F38/F$22 -> -0.00094352392 | G39: =G38/G$22 -> 0.011996929 | H39: =H38/H$22 -> 0.017206066 | I39: =I38/I$22 -> 0.01015989 | J39: =J38/J$22 -> 0.012 | K39: =K38/K$22 -> 0.012 | L39: =L38/L$22 -> 0.012 | M39: =M38/M$22 -> 0.012 | N39: =N38/N$22 -> 0.012
J40: 1 | K40: =J40+1 -> 2 | L40: =K40+1 -> 3 | M40: =L40+1 -> 4 | N40: =M40+1 -> 5
A41: x | B41: DCF | E41: 2021 | F41: =E41+1 -> 2022 | G41: =F41+1 -> 2023 | H41: =G41+1 -> 2024 | I41: =H41+1 -> 2025 | J41: =I41+1 -> 2026 | K41: =J41+1 -> 2027 | L41: =K41+1 -> 2028 | M41: =L41+1 -> 2029 | N41: =M41+1 -> 2030
B42: Revenue | E42: =E22 -> 11294 | F42: =F22 -> 11158 | G42: =G22 -> 11790 | H42: =H22 -> 12347 | I42: =I22 -> 12652 | J42: =I42*(1+J43) -> 12968.3 | K42: =J42*(1+K43) -> 13292.507 | L42: =K42*(1+L43) -> 13558.358 | M42: =L42*(1+M43) -> 13829.525 | N42: =M42*(1+N43) -> 14106.115
B43: % growth | F43: =F42/E42-1 -> -0.012041792 | G43: =G42/F42-1 -> 0.056640975 | H43: =H42/G42-1 -> 0.047243427 | I43: =I42/H42-1 -> 0.024702357 | J43: =J23 -> 0.025 | K43: =K23 -> 0.025 | L43: =L23 -> 0.02 | M43: =M23 -> 0.02 | N43: =N23 -> 0.02
B45: EBIT | E45: =E25 -> 1446 | F45: =F25 -> 1520 | G45: =G25 -> 1614 | H45: =H25 -> 1907 | I45: =I25 -> 2130 | J45: =J46*J42 -> 2593.66 | K45: =K46*K42 -> 2698.379 | L45: =L46*L42 -> 2793.0217 | M45: =M46*M42 -> 2876.5412 | N45: =N46*N42 -> 2962.2842
B46: % margin | E46: =E45/E42 -> 0.12803258 | F46: =F45/F42 -> 0.13622513 | G46: =G45/G42 -> 0.13689567 | H46: =H45/H42 -> 0.15445047 | I46: =I45/I42 -> 0.16835283 | J46: =J26 -> 0.2 | K46: =K26 -> 0.203 | L46: =L26 -> 0.206 | M46: =M26 -> 0.208 | N46: =N26 -> 0.21
B48: Taxes | E48: =E28 -> 361.5 | F48: =F28 -> 380 | G48: =G28 -> 403.5 | H48: =H28 -> 476.75 | I48: =I28 -> 532.5 | J48: =J49*J45 -> 648.415 | K48: =K49*K45 -> 674.59476 | L48: =L49*L45 -> 698.25542 | M48: =M49*M45 -> 719.13529 | N48: =N49*N45 -> 740.57105
B49: % of EBIT | E49: =E48/E45 -> 0.25 | F49: =F48/F45 -> 0.25 | G49: =G48/G45 -> 0.25 | H49: =H48/H45 -> 0.25 | I49: =I48/I45 -> 0.25 | J49: =J29 -> 0.25 | K49: =K29 -> 0.25 | L49: =L29 -> 0.25 | M49: =M29 -> 0.25 | N49: =N29 -> 0.25
B51: NOPAT | J51: =J45-J48 -> 1945.245 | K51: =K45-K48 -> 2023.7843 | L51: =L45-L48 -> 2094.7663 | M51: =M45-M48 -> 2157.4059 | N51: =N45-N48 -> 2221.7132
B53: D&A | E53: =E32 -> 2561 | F53: =F32 -> 2444 | G53: =G32 -> 2500 | H53: =H32 -> 2524 | I53: =I32 -> 2547 | J53: =J32 -> 2528.8185 | K53: =K32 -> 2525.5764 | L53: =L32 -> 2508.2962 | ... N53: =N32 -> 2510.8885
B54: % of sales | E54: =E53/E$42 -> 0.22675757 | F54: =F53/F$42 -> 0.21903567 | G54: =G53/G$42 -> 0.21204411 | H54: =H53/H$42 -> 0.20442213 | I54: =I53/I$42 -> 0.20131205 | J54: =J53/J$42 -> 0.195 | K54: =K53/K$42 -> 0.19 | L54: =L53/L$42 -> 0.185 | ... N54: =N53/N$42 -> 0.178
B56: CapEx | E56: =E35 -> 1905 | F56: =F35 -> 1872 | G56: =G35 -> 2049 | H56: =H35 -> 1919 | I56: =I35 -> 2250 | J56: =J35 -> 2334.294 | K56: =K35 -> 2392.6513 | L56: =L35 -> 2413.3877 | ... N56: =N35 -> 2510.8885
...

Sheet WACC TSystems
B2: WACC
A4: x | B4: WACC
B5: WACC = (% Equity x Cost of Equity) + (% Debt x Cost of Debt x (1 -Tax rate))
B6: Cost of Equity = Risk Free Rate + (Beta x (Expected Market Return - Risk Free Rate))
B8: Debt | D8: 143603000000
B9: % Debt | D9: =D8/D20 -> 0.51414772
B10: Cost of Debt | D10: 0.051
B11: Tax Rate | D11: 0.25
B13: Equity Value | D13: 1.357e+11
B14: % Equity | D14: =D13/D20 -> 0.48585228
B15: Cost of Equity | D15: =D16+D17*D18 -> 0.07575
B16: Risk Free Rate | D16: 0.029
B17: Beta | D17: 0.85
B18: Market Risk Premium | D18: 0.055
B20: Debt + Equity | D20: =D8+D13 -> 279303000000
A22: x | B22: WACC | D22: =(D9*D10*(1-D11))+(D14*D15) -> 0.056469461

Sheet 07_TSystems DCF
B2: T-Systems DCF
A5: x | B5: Assumptions
B6: Valuation Assumptions
B7: WACC | D7: ='WACC TSystems'!D22 -> 0.056469461
B8: TGR | D8: 0.015
B9: Tax Rate | D9: 0.31
B11: Operating Assumptions
B12: T-Systems | E12: 2026E | F12: 2027E | G12: 2028E | H12: 2029E | I12: 2030E
B13: Revenue Growth % | E13: 0.025 | F13: 0.025 | G13: 0.02 | H13: 0.02 | I13: 0.02
B14: EBIT Margin % | E14: 0.045 | F14: 0.048 | G14: 0.05 | H14: 0.054 | I14: 0.057
B15: D&A % of Revenue | E15: 0.06 | F15: 0.055 | G15: 0.055 | H15: 0.052 | I15: 0.048
B16: CapEx % of Revenue | E16: 0.052 | F16: 0.05 | G16: 0.048 | H16: 0.045 | I16: 0.048
B17: Change in NWC % of Revenue | E17: 0.012 | F17: 0.012 | G17: 0.012 | H17: 0.012 | I17: 0.012
J20: 1 | K20: =J20+1 -> 2 | L20: =K20+1 -> 3 | M20: =L20+1 -> 4 | N20: =M20+1 -> 5
A21: x | B21: Income Statement | E21: 2021 | F21: =E21+1 -> 2022 | G21: =F21+1 -> 2023 | H21: =G21+1 -> 2024 | I21: =H21+1 -> 2025 | J21: =I21+1 -> 2026 | K21: =J21+1 -> 2027 | L21: =K21+1 -> 2028 | M21: =L21+1 -> 2029 | N21: =M21+1 -> 2030
B22: Revenue | E22: ='04_Segment Financials'!C29 -> 3759 | F22: ='04_Segment Financials'!D29 -> 3811 | G22: ='04_Segment Financials'!E29 -> 3896 | H22: ='04_Segment Financials'!F29 -> 4004 | I22: ='04_Segment Financials'!G29 -> 4103 | J22: =I22*(1+E13) -> 4205.575 | K22: =J22*(1+F13) -> 4310.7144 | L22: =K22*(1+G13) -> 4396.9287 | M22: =L22*(1+H13) -> 4484.8672 | N22: =M22*(1+I13) -> 4574.5646
B23: % growth | E23: - | F23: =F22/E22-1 -> 0.013833466 | G23: =G22/F22-1 -> 0.022303857 | H23: =H22/G22-1 -> 0.027720739 | I23: =I22/H22-1 -> 0.024725275 | J23: =J22/I22-1 -> 0.025 | K23: =K22/J22-1 -> 0.025 | L23: =L22/K22-1 -> 0.02 | M23: =M22/L22-1 -> 0.02 | N23: =N22/M22-1 -> 0.02
B25: EBIT | E25: ='04_Segment Financials'!C33 -> 28 | F25: ='04_Segment Financials'!D33 -> 56 | G25: ='04_Segment Financials'!E33 -> 103 | H25: ='04_Segment Financials'!F33 -> 148 | I25: ='04_Segment Financials'!G33 -> 175 | J25: =J22*E14 -> 189.25087 | K25: =K22*F14 -> 206.91429 | L25: =L22*G14 -> 219.84643 | M25: =M22*H14 -> 242.18283 | N25: =N22*I14 -> 260.75018
B26: % of sales | E26: =E25/E$22 -> 0.0074487896 | F26: =F25/F$22 -> 0.014694306 | G26: =G25/G$22 -> 0.026437372 | H26: =H25/H$22 -> 0.036963037 | I26: =I25/I$22 -> 0.042651718 | J26: =J25/J$22 -> 0.045 | K26: =K25/K$22 -> 0.048 | L26: =L25/L$22 -> 0.05 | ... N26: =N25/N$22 -> 0.057
B28: Taxes | E28: =E25*$D$9 -> 8.68 | F28: =F25*$D$9 -> 17.36 | G28: =G25*$D$9 -> 31.93 | H28: =H25*$D$9 -> 45.88 | I28: =I25*$D$9 -> 54.25 | J28: =J25*$D$9 -> 58.667771 | K28: =K25*$D$9 -> 64.14343 | L28: =L25*$D$9 -> 68.152394 | ... N28: =N25*$D$9 -> 80.832556
B29: % of EBIT | E29: =E28/E$25 -> 0.31 | F29: =F28/F$25 -> 0.31 | G29: =G28/G$25 -> 0.31 | H29: =H28/H$25 -> 0.31 | I29: =I28/I$25 -> 0.31 | J29: =J28/J$25 -> 0.31 | K29: =K28/K$25 -> 0.31 | L29: =L28/L$25 -> 0.31 | ... N29: =N28/N$25 -> 0.31
A31: x | B31: Cash Flow Items | E31: 2021 | F31: =E31+1 -> 2022 | G31: =F31+1 -> 2023 | H31: =G31+1 -> 2024 | I31: =H31+1 -> 2025 | J31: =I31+1 -> 2026 | K31: =J31+1 -> 2027 | L31: =K31+1 -> 2028 | M31: =L31+1 -> 2029 | N31: =M31+1 -> 2030
B32: D&A | E32: ='04_Segment Financials'!C35 -> 243 | F32: ='04_Segment Financials'!D35 -> 228 | G32: ='04_Segment Financials'!E35 -> 218 | H32: ='04_Segment Financials'!F35 -> 221 | I32: ='04_Segment Financials'!G35 -> 252 | J32: =J22*E15 -> 252.3345 | K32: =K22*F15 -> 237.08929 | L32: =L22*G15 -> 241.83108 | M32: =M22*H15 -> 233.2131 | N32: =N22*I15 -> 219.5791
B33: % of sales | E33: =E32/E$22 -> 0.064644852 | F33: =F32/F$22 -> 0.059826817 | G33: =G32/G$22 -> 0.055954825 | H33: =H32/H$22 -> 0.055194805 | I33: =I32/I$22 -> 0.061418474 | J33: =J32/J$22 -> 0.06 | K33: =K32/K$22 -> 0.055 | L33: =L32/L$22 -> 0.055 | ... N33: =N32/N$22 -> 0.048
B35: CapEx | E35: ='04_Segment Financials'!C37 -> 235 | F35: ='04_Segment Financials'!D37 -> 221 | G35: ='04_Segment Financials'!E37 -> 210 | H35: ='04_Segment Financials'!F37 -> 229 | I35: ='04_Segment Financials'!G37 -> 220 | J35: =J22*E16 -> 218.6899 | K35: =K22*F16 -> 215.53572 | L35: =L22*G16 -> 211.05258 | M35: =M22*H16 -> 201.81903 | N35: =N22*I16 -> 219.5791
B36: % of sales | E36: =E35/E$22 -> 0.062516627 | F36: =F35/F$22 -> 0.057990029 | G36: =G35/G$22 -> 0.053901437 | H36: =H35/H$22 -> 0.057192807 | I36: =I35/I$22 -> 0.053619303 | J36: =J35/J$22 -> 0.052 | K36: =K35/K$22 -> 0.05 | L36: =L35/L$22 -> 0.048 | ... N36: =N35/N$22 -> 0.048
B38: Change in NWC | E38: - | F38: ='04_Segment Financials'!D59 -> -0.69924837 | G38: ='04_Segment Financials'!E59 -> 43.168849 | H38: ='04_Segment Financials'!F59 -> 66.039685 | I38: ='04_Segment Financials'!G59 -> 41.690931 | J38: =J22*E17 -> 50.4669 | K38: =K22*F17 -> 51.728572 | L38: =L22*G17 -> 52.763144 | M38: =M22*H17 -> 53.818407 | N38: =N22*I17 -> 54.894775
B39: % of sales | F39: =F38/F$22 -> -0.0001834816 | G39: =G38/G$22 -> 0.0110803 | H39: =H38/H$22 -> 0.016493428 | I39: =I38/I$22 -> 0.010161085 | J39: =J38/J$22 -> 0.012 | K39: =K38/K$22 -> 0.012 | L39: =L38/L$22 -> 0.012 | M39: =M38/M$22 -> 0.012 | N39: =N38/N$22 -> 0.012
J40: 1 | K40: =J40+1 -> 2 | L40: =K40+1 -> 3 | M40: =L40+1 -> 4 | N40: =M40+1 -> 5
A41: x | B41: DCF | E41: 2021 | F41: =E41+1 -> 2022 | G41: =F41+1 -> 2023 | H41: =G41+1 -> 2024 | I41: =H41+1 -> 2025 | J41: =I41+1 -> 2026 | K41: =J41+1 -> 2027 | L41: =K41+1 -> 2028 | M41: =L41+1 -> 2029 | N41: =M41+1 -> 2030
B42: Revenue | E42: =E22 -> 3759 | F42: =F22 -> 3811 | G42: =G22 -> 3896 | H42: =H22 -> 4004 | I42: =I22 -> 4103 | J42: =I42*(1+J43) -> 4205.575 | K42: =J42*(1+K43) -> 4310.7144 | L42: =K42*(1+L43) -> 4396.9287 | M42: =L42*(1+M43) -> 4484.8672 | N42: =M42*(1+N43) -> 4574.5646
B43: % growth | F43: =F42/E42-1 -> 0.013833466 | G43: =G42/F42-1 -> 0.022303857 | H43: =H42/G42-1 -> 0.027720739 | I43: =I42/H42-1 -> 0.024725275 | J43: =J23 -> 0.025 | K43: =K23 -> 0.025 | L43: =L23 -> 0.02 | M43: =M23 -> 0.02 | N43: =N23 -> 0.02
B45: EBIT | E45: =E25 -> 28 | F45: =F25 -> 56 | G45: =G25 -> 103 | H45: =H25 -> 148 | I45: =I25 -> 175 | J45: =J46*J42 -> 189.25087 | K45: =K46*K42 -> 206.91429 | L45: =L46*L42 -> 219.84643 | M45: =M46*M42 -> 242.18283 | N45: =N46*N42 -> 260.75018
B46: % margin | E46: =E45/E42 -> 0.0074487896 | F46: =F45/F42 -> 0.014694306 | G46: =G45/G42 -> 0.026437372 | H46: =H45/H42 -> 0.036963037 | I46: =I45/I42 -> 0.042651718 | J46: =J26 -> 0.045 | K46: =K26 -> 0.048 | L46: =L26 -> 0.05 | M46: =M26 -> 0.054 | N46: =N26 -> 0.057
B48: Taxes | E48: =E28 -> 8.68 | F48: =F28 -> 17.36 | G48: =G28 -> 31.93 | H48: =H28 -> 45.88 | I48: =I28 -> 54.25 | J48: =J49*J45 -> 58.667771 | K48: =K49*K45 -> 64.14343 | L48: =L49*L45 -> 68.152394 | M48: =M49*M45 -> 75.076678 | N48: =N49*N45 -> 80.832556
B49: % of EBIT | E49: =E48/E45 -> 0.31 | F49: =F48/F45 -> 0.31 | G49: =G48/G45 -> 0.31 | H49: =H48/H45 -> 0.31 | I49: =I48/I45 -> 0.31 | J49: =J29 -> 0.31 | K49: =K29 -> 0.31 | L49: =L29 -> 0.31 | M49: =M29 -> 0.31 | N49: =N29 -> 0.31
B51: NOPAT | J51: =J45-J48 -> 130.5831 | K51: =K45-K48 -> 142.77086 | L51: =L45-L48 -> 151.69404 | M51: =M45-M48 -> 167.10615 | N51: =N45-N48 -> 179.91762
B53: D&A | E53: =E32 -> 243 | F53: =F32 -> 228 | G53: =G32 -> 218 | H53: =H32 -> 221 | I53: =I32 -> 252 | J53: =J32 -> 252.3345 | K53: =K32 -> 237.08929 | L53: =L32 -> 241.83108 | ... N53: =N32 -> 219.5791
B54: % of sales | E54: =E53/E$42 -> 0.064644852 | F54: =F53/F$42 -> 0.059826817 | G54: =G53/G$42 -> 0.055954825 | H54: =H53/H$42 -> 0.055194805 | I54: =I53/I$42 -> 0.061418474 | J54: =J53/J$42 -> 0.06 | K54: =K53/K$42 -> 0.055 | L54: =L53/L$42 -> 0.055 | ... N54: =N53/N$42 -> 0.048
B56: CapEx | E56: =E35 -> 235 | F56: =F35 -> 221 | G56: =G35 -> 210 | H56: =H35 -> 229 | I56: =I35 -> 220 | J56: =J35 -> 218.6899 | K56: =K35 -> 215.53572 | L56: =L35 -> 211.05258 | ... N56: =N35 -> 219.5791
...

Sheet 08_TMUS Stake
B2: TMUS Stake
A5: x | B5: Assumptions
B6: TMUS Share Price ($) | E6: 189.1
B7: Shares Outstanding (m) | E7: 1100
B8: Market Cap ($m) | E8: =E7*E6 -> 208010
B9: DT Ownership % | E9: 0.528
B10: DT Stake Value ($m) | E10: =E9*E8 -> 109829.28
B11: EUR/USD | E11: 1.1567
B12: DT Stake Value (€m) | E12: =E10/E11 -> 94950.532
B14: TMUS Stake Value for SOTP | E14: =E12 -> 94950.532

Sheet 09_Trading Comps
B2: Comparable Company Analysis
B4: Market Data
A5: x | B5: Company Name | C5: Ticker | D5: Stock Price | E5: Shares (m) | F5: Market Cap | G5: (+) Net Debt | H5: (+) Minorities | I5: (=) Enterprise Value
B6: Deutsche Telekom AG (European Business Only) | C6: DTE.DE | D6: 27.85 | E6: ='11_SOTP'!F14 -> 4960 | F6: - | G6: 38500 | H6: 0 | I6: ='11_SOTP'!F7+'11_SOTP'!F8+'11_SOTP'!F9 -> 147549.39 | K6: EUR/EUR | L6: 1
B7: Orange SA | C7: ORA.PA | D7: 17.84 | E7: 2660 | F7: =D7*E7*$L$6 -> 47454.4 | G7: 22526 | H7: 268 | I7: =F7+G7+H7 -> 70248.4 | K7: GBP/EUR | L7: 1.1585
B8: Vodafone Group | C8: VOD.L | D8: 1.1515 | E8: 23027 | F8: =D8*E8*$L$7 -> 30718.312 | G8: 25400 | H8: 1100 | I8: =F8+G8+H8 -> 57218.312 | K8: CHF/EUR | L8: 1.0845
B9: Telefónica SA | C9: TEF.MC | D9: 3.94 | E9: 5750 | F9: =D9*E9*$L$6 -> 22655 | G9: 26824 | H9: 163 | I9: =F9+G9+H9 -> 49642 | K9: USD/EUR | L9: 0.8645
B10: KPN NV | C10: KPN.AS | D10: 4.46 | E10: 3783 | F10: =D10*E10*$L$6 -> 16872.18 | G10: 6774 | H10: 0 | I10: =F10+G10+H10 -> 23646.18
B11: Swisscom AG | C11: SCMN.SW | D11: 656.5 | E11: 51.8 | F11: =D11*E11*$L$8 -> 36880.266 | G11: =15920*$L$8 -> 17265.24 | H11: 0 | I11: =F11+G11+H11 -> 54145.506
B13: Financials
A14: x | B14: Company Name | C14: Revenue (€m) | D14: EBITDA (€m) | E14: EBIT (€m) | F14: EV/Revenue | G14: EV/EBITDA | H14: EV/EBIT
B15: Deutsche Telekom AG (European Business Only) | C15: ='04_Segment Financials'!J6 -> 42365 | D15: ='04_Segment Financials'!J7 -> 15798 | E15: ='04_Segment Financials'!J8 -> 8519 | F15: =I6/C15 -> 3.4828133 | G15: =I6/D15 -> 9.3397511 | H15: =I6/E15 -> 17.320036
B16: Orange SA | C16: 44680 | D16: 14360 | E16: 6141 | F16: =I7/C16 -> 1.572256 | G16: =I7/D16 -> 4.8919499 | H16: =I7/E16 -> 11.439244
B17: Vodafone Group | C17: 44451 | D17: 12998 | E17: 5108 | F17: =I8/C17 -> 1.2872221 | G17: =I8/D17 -> 4.4020858 | H17: =I8/E17 -> 11.201705
B18: Telefónica SA | C18: 33542 | D18: 11851 | E18: 4773 | F18: =I9/C18 -> 1.4799952 | G18: =I9/D18 -> 4.1888448 | H18: =I9/E18 -> 10.400587
B19: KPN NV | C19: 5913 | D19: 2805 | E19: 1491 | F19: =I10/C19 -> 3.9990157 | G19: =I10/D19 -> 8.4300107 | H19: =I10/E19 -> 15.859276
B20: Swisscom AG | C20: 14720 | D20: 6674 | E20: 2094 | F20: =I11/C20 -> 3.6783632 | G20: =I11/D20 -> 8.1129017 | H20: =I11/E20 -> 25.857453
B21: Mean | C21: - | D21: - | E21: - | F21: =AVERAGE(F16:F20) -> 2.4033705 | G21: =AVERAGE(G16:G20) -> 6.0051586 | H21: =AVERAGE(H16:H20) -> 14.951653
B22: Median | C22: - | D22: - | E22: - | F22: =MEDIAN(F16:F20) -> 1.572256 | G22: =MEDIAN(G16:G20) -> 4.8919499 | H22: =MEDIAN(H16:H20) -> 11.439244
A24: x | B24: Method for DT Value | C24: Implied EV (€m)
B25: Revenue Method | C25: =F22*C15 -> 66608.627
B26: EBITDA Method | C26: =G22*D15 -> 77283.024
B27: EBIT Method | C27: =H22*E15 -> 97450.923
B29: Base
B30: Selected EV (EBITDA) | C30: =C26 -> 77283.024 | E30: Low Case: | F30: =C42 -> 24.810314
B31: =_xlfn.CONCAT("(-) Adjusted Net Debt") -> (-) Adjusted Net Debt | C31: =G6 -> 38500 | E31: Base Case: | F31: =C34 -> 26.96241
B32: =_xlfn.CONCAT("(=) Equity Value") -> (=) Equity Value | C32: =C30-C31+'08_TMUS Stake'!E14 -> 133733.56 | E32: High Case: | F32: =C50 -> 31.028519
B33: =_xlfn.CONCAT("(÷) Shares Outstanding") -> (÷) Shares Outstanding | C33: ='11_SOTP'!F14 -> 4960
B34: =_xlfn.CONCAT("(=) Implied Share Price") -> (=) Implied Share Price | C34: =C32/C33 -> 26.96241
B37: Low
B38: Selected EV (Revenue) | C38: =C25 -> 66608.627
B39: =_xlfn.CONCAT("(-) Adjusted Net Debt") -> (-) Adjusted Net Debt | C39: =G6 -> 38500
B40: =_xlfn.CONCAT("(=) Equity Value") -> (=) Equity Value | C40: =C38-C39+'08_TMUS Stake'!E14 -> 123059.16
B41: =_xlfn.CONCAT("(÷) Shares Outstanding") -> (÷) Shares Outstanding | C41: =C33 -> 4960
B42: =_xlfn.CONCAT("(=) Implied Share Price") -> (=) Implied Share Price | C42: =C40/C41 -> 24.810314
B45: High
B46: Selected EV (EBIT) | C46: =C27 -> 97450.923
B47: =_xlfn.CONCAT("(-) Adjusted Net Debt") -> (-) Adjusted Net Debt | C47: =G6 -> 38500
B48: =_xlfn.CONCAT("(=) Equity Value") -> (=) Equity Value | C48: =C46-C47+'08_TMUS Stake'!E14 -> 153901.45
B49: =_xlfn.CONCAT("(÷) Shares Outstanding") -> (÷) Shares Outstanding | C49: =C33 -> 4960
...

Sheet 10_Precedent Transactions
B2: Precedent Transactions
A4: x | B4: Deal Information | C4: Announcement Date | D4: Acquirer | E4: Target | F4: Country | G4: Deal Type | H4: Enterprise Value (€m)
B5: Deal 1 | C5: =DATE(2024,3,1) -> 45352 | D5: Orange | E5: MasMovil | F5: Spain | G5: Merger / JV (combined basis) | H5: 18600
B6: Deal 2 | C6: =DATE(2023,6,1) -> 45078 | D6: Vodafone UK | E6: Three UK | F6: United Kingdom | G6: Merger / JV (combined basis) | H6: 17500
B7: Deal 3 | C7: =DATE(2023,10,1) -> 45200 | D7: Zegona Communications | E7: Vodafone Spain | F7: Spain | G7: Acquisition | H7: 5000
B8: Deal 4 | C8: 45323 | D8: Bouygues Telecom | E8: La Poste Telecom | F8: France | G8: Acquisition | H8: 963
B9: Deal 5 | C9: =DATE(2021,5,1) -> 44317 | D9: Virgin Media (Liberty) | E9: O2 UK (Telefonica) | F9: United Kingdom | G9: Merger / JV (combined basis) | H9: 36000
A12: x | B12: Target Financials (€m) | C12: Revenue | D12: EBITDA | E12: EBIT
B13: Orange | C13: 7400 | D13: 2360 | E13: 910
B14: Vodafone UK | C14: 7850 | D14: 2010 | E14: 740
B15: Zegona Communications | C15: 3900 | D15: 1310 | E15: 410
B16: Bouygues Telecom | C16: 310 | D16: 85 | E16: 28
B17: Virgin Media (Liberty) | C17: 12500 | D17: 4350 | E17: 1680
A19: x | B19: Transaction Multiples | C19: EV/Revenue | D19: EV/EBITDA | E19: EV/EBIT
B20: Orange | C20: =H5/C13 -> 2.5135135 | D20: =H5/D13 -> 7.8813559 | E20: =H5/E13 -> 20.43956
B21: Vodafone UK | C21: =H6/C14 -> 2.2292994 | D21: =H6/D14 -> 8.7064677 | E21: =H6/E14 -> 23.648649
B22: Zegona Communications | C22: =H7/C15 -> 1.2820513 | D22: =H7/D15 -> 3.8167939 | E22: =H7/E15 -> 12.195122
B23: Bouygues Telecom | C23: =H8/C16 -> 3.1064516 | D23: =H8/D16 -> 11.329412 | E23: =H8/E16 -> 34.392857
B24: Virgin Media (Liberty) | C24: =H9/C17 -> 2.88 | D24: =H9/D17 -> 8.2758621 | E24: =H9/E17 -> 21.428571
A26: x | B26: Statistic | C26: EV/Revenue | D26: EV/EBITDA | E26: EV/EBIT
B27: Mean | C27: =AVERAGE(C20:C24) -> 2.4022632 | D27: =AVERAGE(D20:D24) -> 8.0019783 | E27: =AVERAGE(E20:E24) -> 22.420952
B28: Median | C28: =MEDIAN(C20:C24) -> 2.5135135 | D28: =MEDIAN(D20:D24) -> 8.2758621 | E28: =MEDIAN(E20:E24) -> 21.428571
B29: Min | C29: =MIN(C20:C24) -> 1.2820513 | D29: =MIN(D20:D24) -> 3.8167939 | E29: =MIN(E20:E24) -> 12.195122
B30: Max | C30: =MAX(C20:C24) -> 3.1064516 | D30: =MAX(D20:D24) -> 11.329412 | E30: =MAX(E20:E24) -> 34.392857
A33: x | B33: Method for DT Value | C33: Implied EV (€m)
B34: Revenue Method | C34: ='03_Historical Financials'!G6*'10_Precedent Transactions'!C28 -> 299311.7
B35: EBITDA Method | C35: ='03_Historical Financials'!G7*'10_Precedent Transactions'!D28 -> 366157.24
B36: EBIT Method | C36: ='03_Historical Financials'!G10*'10_Precedent Transactions'!E28 -> 531900
B38: High
B39: Selected EV (EBITDA Method) | C39: =C35 -> 366157.24 | E39: Low Case: | F39: =C53 -> 33.369295
B40: =_xlfn.CONCAT("(-) Adjusted Net Debt") -> (-) Adjusted Net Debt | C40: 133800 | E40: Base Case: | F40: =C43 -> 46.846218
B41: =_xlfn.CONCAT("(=) Equity Value") -> (=) Equity Value | C41: =C39-C40 -> 232357.24 | E41: High Case: | F41: -
B42: =_xlfn.CONCAT("(÷) Shares Outstanding") -> (÷) Shares Outstanding | C42: ='11_SOTP'!F14 -> 4960
B43: =_xlfn.CONCAT("(=) Implied Share Price") -> (=) Implied Share Price | C43: =C41/C42 -> 46.846218
B45: Precedent implies a control premium of: | C45: =C43/'11_SOTP'!F16-1 -> 0.13900654
B48: Low
B49: Selected EV (Revenue Method) | C49: =C34 -> 299311.7
B50: =_xlfn.CONCAT("(-) Adjusted Net Debt") -> (-) Adjusted Net Debt | C50: 133800
B51: =_xlfn.CONCAT("(=) Equity Value") -> (=) Equity Value | C51: =C49-C50 -> 165511.7
B52: =_xlfn.CONCAT("(÷) Shares Outstanding") -> (÷) Shares Outstanding | C52: =C42 -> 4960
...

Sheet 11_SOTP
B2: Sum of the Parts Valuation - Telekom
A5: x | B5: SOTP Telekom
B6: Component | F6: Value (€m)
B7: Germany | F7: ='05_Germany DCF'!N67 -> 97918.107
B8: Europe | F8: ='06_Europe DCF'!N67 -> 46774.117
B9: T-Systems | F9: ='07_TSystems DCF'!N67 -> 2857.1632
B10: TMUS Stake | F10: ='08_TMUS Stake'!E14 -> 94950.532
B11: Gross Asset Value | F11: =SUM(F7:F10) -> 242499.92
B12: =_xlfn.CONCAT(" - Net Debt excl. TMUS") -> - Net Debt excl. TMUS | F12: 38500 | G12: Group Net Debt roughly 133,800 and TMUS holds roughly 95,300 of that debt on its own balance sheet
B13: Implied Parent Equity Value | F13: =F11-F12 -> 203999.92
B14: Shares Outstanding | F14: 4960
B16: Implied Target Share Price (€) | F16: =F13/F14 -> 41.129016
B19: Low Case: | C19: =F16*0.9 -> 37.016114
B20: Base Case: | C20: =F16 -> 41.129016
B21: High Case: | C21: =F16*1.1 -> 45.241918

Sheet 12_Football Fields
B2: Football Field
A5: x | B5: Method | C5: Low | D5: Base | E5: High | G5: Method | H5: Start | I5: Width
B6: Trading Comps | C6: ='09_Trading Comps'!F30 -> 24.810314 | D6: ='09_Trading Comps'!F31 -> 26.96241 | E6: ='09_Trading Comps'!F32 -> 31.028519 | G6: Trading Comps | H6: =C6 -> 24.810314 | I6: =E6-C6 -> 6.2182048
B7: SOTP | C7: ='11_SOTP'!C19 -> 37.016114 | D7: ='11_SOTP'!C20 -> 41.129016 | E7: ='11_SOTP'!C21 -> 45.241918 | G7: SOTP | H7: =C7 -> 37.016114 | I7: =E7-C7 -> 8.2258032
B8: Precedents | C8: ='10_Precedent Transactions'!F39 -> 33.369295 | D8: ='10_Precedent Transactions'!F40 -> 46.846218 | G8: Precedents | H8: =C8 -> 33.369295 | I8: =D8-C8 -> 13.476923
G12: Current Share Price of DT (27€)

Sheet 13_Sensitivity
B2: Sensitivity Analysis
B5: Because of the multi-segment SOTP framework where separate discountrates where used for individual operating segments and then a market based valuation wa used for the TMUS stake, a consolidated WACC/TGR senstivity was not noe as it would not accurately refelct the underlying valuation methodology.
